Workbook

Sheet Assumptions
A1: Cost & pricing model — assumptions
A2: Every yellow cell is an input. Everything on the other sheets is a formula over this one. Lines marked MEASURE are estimates standing in for data you can read out of ai_events and your cloud bill — replace them first.
A4: Assumption | B4: Value | C4: Source / note
A5: § Currency and tax
A6: USD → INR | B6: 95.6 | C6: Spot rate, 30 Aug 2026. Re-check before quoting.
A7: GST on Indian invoices | B7: 0.18 | C7: Pass-through, not cost. All prices below are ex-GST.
A8: § AI — LLM token rates (per 1M tokens, USD)
A9: Workhorse model input | B9: 1 | C9: Claude Haiku 4.5 — tutor, grading, extraction.
A10: Workhorse model output | B10: 5 | C10: Claude Haiku 4.5.
A11: Analysis model input | B11: 2 | C11: Claude Sonnet 5 — mock scoring, reports.
A12: Analysis model output | B12: 10 | C12: Claude Sonnet 5.
A13: § AI Assist — usage per AI-active student per month
A14: Tutor questions | B14: 30 | C14: Site claims 400+ questions over a course; 30/mo is that pace.
A15: Tutor input tokens per question | B15: 4000 | C15: Syllabus context, largely prompt-cached.
A16: Tutor output tokens per question | B16: 800 | C16: MEASURE — replace with your ai_events median.
A17: Graded items per month | B17: 8 | C17: Assignments plus quizzes.
A18: Grading input tokens per item | B18: 5000 | C18: MEASURE — replace with measured.
A19: Grading output tokens per item | B19: 1000 | C19: MEASURE — replace with measured.
A20: Mock interviews analysed | B20: 4 | C20: Weekly mocks, per the programme.
A21: Mock analysis input tokens | B21: 15000 | C21: Transcript plus rubric.
A22: Mock analysis output tokens | B22: 2000 | C22: Per-dimension scores and gap report.
A23: § AI Voice — the metered line
A24: Voice platform cost per minute (USD) | B24: 0.11 | C24: Vapi/Retell realistic all-in: $0.07–0.15/min.
A25: Telephony cost per minute (USD) | B25: 0.02 | C25: Outbound India; confirm with your carrier.
A26: Voice minutes per mock interview | B26: 15 | C26: One mock = one 15-minute call.
A27: § Messaging
A28: WhatsApp utility messages per student per month | B28: 12 | C28: Nudges, reminders, results.
A29: WhatsApp utility rate (INR, ex-GST) | B29: 0.115 | C29: Meta India per-message rate, 2026.
A30: WhatsApp marketing messages per student per month | B30: 2 | C30: Campaigns.
A31: WhatsApp marketing rate (INR, ex-GST) | B31: 0.8631 | C31: Meta India per-message rate, 2026.
A32: § Infrastructure — built up from published unit rates
A33: Video GB streamed per active student per month | B33: 5 | C33: ~10 hrs at 720p (≈0.5 GB/hr).
A34: CDN egress rate per GB (USD) | B34: 0.02 | C34: bunny.net: Asia standard $0.03, volume from $0.005.
A35: Recording GB retained per active student | B35: 1.8 | C35: 4 mocks × 15 min × 0.15 GB, 90-day retention.
A36: Object storage rate per GB-month (USD) | B36: 0.015 | C36: Cloudflare R2 Standard, zero egress.
A37: App compute + DB per active student per month (USD) | B37: 0.05 | C37: MEASURE — amortise tenant 1's bill.
A38: Platform base cost per tenant per month (USD) | B38: 20 | C38: DB share, monitoring, backups, TLS, WAF.
A39: § Utilisation
A40: Monthly-active share of enrolled seats | B40: 0.65 | C40: An enrolled seat is not a billable-cost seat every month.
A41: § Operations
...

Sheet Unit economics
A1: What one student costs us, per month
A2: Three stacks, three orders of magnitude. This page is why AI Voice is metered and the platform is not.
A4: Cost line | B4: Formula basis | C4: USD / active student / month
A5: Platform — charged in the licence
A6: Video delivery | B6: GB streamed × CDN rate | C6: =Assumptions!$B$33*Assumptions!$B$34
A7: Recording storage | B7: GB retained × object storage rate | C7: =Assumptions!$B$35*Assumptions!$B$36
A8: App compute & database | B8: amortised per active student | C8: =Assumptions!$B$37
A9: WhatsApp messaging | B9: (utility + marketing) ÷ FX | C9: =(Assumptions!$B$28*Assumptions!$B$29+Assumptions!$B$30*Assumptions!$B$31)/Assumptions!$B$6
A10: Platform — charged in the licence subtotal | C10: =SUM(C6:C9)
A12: AI Assist — sold as a per-student pack
A13: AI tutor | B13: questions × (in×rate + out×rate) | C13: =Assumptions!$B$14*(Assumptions!$B$15/1000000*Assumptions!$B$9+Assumptions!$B$16/1000000*Assumptions!$B$10)
A14: Grading & quizzes | B14: items × (in×rate + out×rate) | C14: =Assumptions!$B$17*(Assumptions!$B$18/1000000*Assumptions!$B$9+Assumptions!$B$19/1000000*Assumptions!$B$10)
A15: Mock interview analysis | B15: mocks × (in×rate + out×rate) | C15: =Assumptions!$B$20*(Assumptions!$B$21/1000000*Assumptions!$B$11+Assumptions!$B$22/1000000*Assumptions!$B$12)
A16: AI Assist — sold as a per-student pack subtotal | C16: =SUM(C13:C15)
A18: AI Voice — metered by the minute
A19: Voice platform, one 15-min mock | B19: minutes × platform rate | C19: =Assumptions!$B$26*Assumptions!$B$24
A20: Telephony, one 15-min mock | B20: minutes × telephony rate | C20: =Assumptions!$B$26*Assumptions!$B$25
A21: AI Voice — metered by the minute subtotal | C21: =SUM(C19:C20)
A23: Reality check — relative size
A24: One month of platform, per student | C24: ='Unit economics'!$C$10
A25: One month of AI Assist, per student | C25: ='Unit economics'!$C$16
A26: ONE 15-minute voice mock | C26: ='Unit economics'!$C$21
A27: Four voice mocks (the weekly programme) | C27: ='Unit economics'!$C$21*4
A29: A student on the full weekly-mock programme costs more in voice minutes than in everything else combined, several times over. Halve the token counts above and the total barely moves; halve the voice minutes and the business changes. That is why the licence covers the platform, AI Assist is a per-student pack, and voice is billed against metered minutes.

Sheet Tier economics
A1: Tier economics — India and International
A2: Cost is modelled bottom-up; price is a round point chosen against the Benchmarks sheet. Each tier includes a small AI allowance so the AI sells itself — sized to stay a minor share of the licence.
A4: Tier | B4: Enrolled seats | C4: Active seats | D4: Platform cost | E4: Tenant cost | F4: Included AI cost | G4: Total cost / mo (USD) | H4: INDIA ₹/mo | I4: Margin — India | J4: INTL $/mo | K4: Margin — Intl
A5: Starter | B5: 100 | C5: =B5*Assumptions!$B$40 | D5: =C5*'Unit economics'!$C$10 | E5: =Assumptions!$B$38+Assumptions!$B$42/Assumptions!$B$6 | F5: =25*'Unit economics'!$C$16+150*(Assumptions!$B$24+Assumptions!$B$25) | G5: =D5+E5+F5 | H5: 24999 | I5: =IFERROR((H5/Assumptions!$B$6-G5)/(H5/Assumptions!$B$6),0) | J5: 499 | K5: =IFERROR((J5-G5)/J5,0)
A6: Growth | B6: 500 | C6: =B6*Assumptions!$B$40 | D6: =C6*'Unit economics'!$C$10 | E6: =Assumptions!$B$38+Assumptions!$B$43/Assumptions!$B$6 | F6: =100*'Unit economics'!$C$16+400*(Assumptions!$B$24+Assumptions!$B$25) | G6: =D6+E6+F6 | H6: 74999 | I6: =IFERROR((H6/Assumptions!$B$6-G6)/(H6/Assumptions!$B$6),0) | J6: 1499 | K6: =IFERROR((J6-G6)/J6,0)
A7: Enterprise | B7: 1500 | C7: =B7*Assumptions!$B$40 | D7: =C7*'Unit economics'!$C$10 | E7: =Assumptions!$B$38+Assumptions!$B$44/Assumptions!$B$6 | F7: =250*'Unit economics'!$C$16+800*(Assumptions!$B$24+Assumptions!$B$25) | G7: =D7+E7+F7 | H7: 199999 | I7: =IFERROR((H7/Assumptions!$B$6-G7)/(H7/Assumptions!$B$6),0) | J7: 3499 | K7: =IFERROR((J7-G7)/J7,0)
A9: Included AI allowance — state this in the order form
A10: Tier | B10: AI Assist students / mo | C10: Voice minutes / mo | D10: =mock interviews / mo | E10: Allowance as % of licence (India)
A11: Starter | B11: 25 | C11: 150 | D11: =B11*0+150/Assumptions!$B$26 | E11: =IFERROR(F5/(H5/Assumptions!$B$6),0)
A12: Growth | B12: 100 | C12: 400 | D12: =B12*0+400/Assumptions!$B$26 | E12: =IFERROR(F6/(H6/Assumptions!$B$6),0)
A13: Enterprise | B13: 250 | C13: 800 | D13: =B13*0+800/Assumptions!$B$26 | E13: =IFERROR(F7/(H7/Assumptions!$B$6),0)
A15: Margins here are GROSS — cost of service only. They exclude R&D, sales and G&A. A 68% gross margin is roughly a 30–40% contribution margin once those are loaded.
A16: India is priced below the International equivalent on purpose. The cost base is dollar-denominated and identical; the Indian anchor price is not. 68% is what this market supports — do not model 82% in India and then discount into a loss.
A17: GST and payment processing are excluded: both are pass-through on collection, not cost of service.
A18: Discount floor: never take a licence below the margin floor on the Assumptions sheet without founder sign-off. Annual prepay = 2 months free (16.7%) is the standard concession; give the discount on term, not on price.

Sheet Packs & fees
A1: What we sell on top of the licence
A2: The licence is software margin. This page is where AI consumption is recovered — at a deliberately lower, honest margin, because it is largely someone else's bill.
A4: Meter | B4: Our cost (USD) | C4: INDIA list | D4: Margin — India | E4: INTL list (USD) | F4: Margin — Intl
A5: AI Assist — per AI-active student / month | B5: ='Unit economics'!$C$16 | C5: 199 | D5: =IFERROR((C5/Assumptions!$B$6-B5)/(C5/Assumptions!$B$6),0) | E5: 3 | F5: =IFERROR((E5-B5)/E5,0)
A6: AI Voice — per minute, our keys | B6: =(Assumptions!$B$24+Assumptions!$B$25) | C6: 25 | D6: =IFERROR((C6/Assumptions!$B$6-B6)/(C6/Assumptions!$B$6),0) | E6: 0.4 | F6: =IFERROR((E6-B6)/E6,0)
A7: AI Voice — per minute, partner's own keys | B7: =(Assumptions!$B$24+Assumptions!$B$25)*0+0.005 | C7: 6 | D7: =IFERROR((C7/Assumptions!$B$6-B7)/(C7/Assumptions!$B$6),0) | E7: 0.1 | F7: =IFERROR((E7-B7)/E7,0)
A8: Extra enrolled seat / month | B8: ='Unit economics'!$C$10*Assumptions!$B$40 | C8: 35 | D8: =IFERROR((C8/Assumptions!$B$6-B8)/(C8/Assumptions!$B$6),0) | E8: 0.6 | F8: =IFERROR((E8-B8)/E8,0)
A10: Voice margin is structurally thinner than software margin — roughly half of the price is a third party's invoice. Do not fix that by raising the per-minute price until it stops selling: fix it by moving high-volume partners onto their own Vapi/Twilio keys, where we charge orchestration only and their voice bill is their own.
A12: Prepaid voice blocks — India
A13: Block | B13: Minutes | C13: Price (INR) | D13: Effective ₹/min | E13: Our cost (USD) | F13: Margin
A14: Trial | B14: 500 | C14: 12499 | D14: =IFERROR(C14/B14,0) | E14: =B14*(Assumptions!$B$24+Assumptions!$B$25) | F14: =IFERROR((C14/Assumptions!$B$6-E14)/(C14/Assumptions!$B$6),0)
A15: Standard | B15: 1000 | C15: 24999 | D15: =IFERROR(C15/B15,0) | E15: =B15*(Assumptions!$B$24+Assumptions!$B$25) | F15: =IFERROR((C15/Assumptions!$B$6-E15)/(C15/Assumptions!$B$6),0)
A16: Volume | B16: 5000 | C16: 114999 | D16: =IFERROR(C16/B16,0) | E16: =B16*(Assumptions!$B$24+Assumptions!$B$25) | F16: =IFERROR((C16/Assumptions!$B$6-E16)/(C16/Assumptions!$B$6),0)
A17: Institutional | B17: 20000 | C17: 419999 | D17: =IFERROR(C17/B17,0) | E17: =B17*(Assumptions!$B$24+Assumptions!$B$25) | F17: =IFERROR((C17/Assumptions!$B$6-E17)/(C17/Assumptions!$B$6),0)
A19: One-time fees
A20: Fee | B20: Our cost (USD) | C20: INDIA list | D20: Margin — India | E20: INTL list (USD) | F20: Margin — Intl
A21: Onboarding & implementation | B21: =Assumptions!$B$45/Assumptions!$B$6 | C21: 125000 | D21: =IFERROR((C21/Assumptions!$B$6-B21)/(C21/Assumptions!$B$6),0) | E21: 2500 | F21: =IFERROR((E21-B21)/E21,0)
A22: Data migration, per source system | B22: =Assumptions!$B$46 | C22: 40000 | D22: =IFERROR((C22/Assumptions!$B$6-B22)/(C22/Assumptions!$B$6),0) | E22: 999 | F22: =IFERROR((E22-B22)/E22,0)
A23: Custom domain + branded app store listing | B23: =300 | C23: 49999 | D23: =IFERROR((C23/Assumptions!$B$6-B23)/(C23/Assumptions!$B$6),0) | E23: 999 | F23: =IFERROR((E23-B23)/E23,0)
A25: Onboarding is a deal-closer, not a profit centre. It may be discounted to cost to win a reference partner — but discount the fee, never the licence, because the licence is what renews.

Sheet Benchmarks
A1: What the market charges
A2: Gathered August 2026. Ranges are as published or as reported by third-party comparison sites — treat quote-gated vendors as indicative, not exact.
A4: Vendor / segment | B4: Published price | C4: Notes | D4: Source
A5: INDIA — LMS / institute platforms
A6: Classplus | B6: ₹3,000 – ₹15,000 / mo | C6: Plus setup ₹15k+ and a transaction commission; SMS/WhatsApp credits extra. | D6: edmingle.com, allcoaching.in (2026)
A7: Teachmint | B7: ₹2,500 – ₹1,25,000 / mo | C7: Free tier exists; setup ₹25k–₹2L reported at the top end. | D7: igniterapp.com, feealert.in (2026)
A8: Learnyst / Edmingle | B8: Entry ₹8,000 – ₹50,000 / yr | C8: Entry-level annual plans for small institutes. | D8: edmingle.com (2026)
A9: INDIA — education CRM
A10: LeadSquared | B10: ₹1,250 – ₹4,500 / user / mo | C10: Lite / Pro / Super, billed annually, ex-GST. Education product is quoted. | D10: Published per-user plans (2026)
A11: Meritto | B11: Priced on application volume | C11: Not per-seat — anchors on forms processed. | D11: softwaresuggest.com (2026)
A12: Market norm | B12: ₹2,000 – ₹5,000 / counsellor / mo | C12: Typical per-seat education CRM band. | D12: vivelead.com (2026)
A13: INTERNATIONAL — LMS
A14: TalentLMS | B14: $119 / mo (40 users) | C14: Free tier to 5 users. | D14: talentlms.com (2026)
A15: LearnWorlds | B15: $249 / mo and up for white-label | C15: White-label gated to the Learning Center plan. | D15: learnworlds.com (2026)
A16: Docebo | B16: $10,000 – $100,000+ / yr | C16: Quote-only, mid-market to enterprise. | D16: selecthub.com (2026)
A17: Multi-client training platforms | B17: £4,000 – £25,000 / yr | C17: Training company running several client portals. | D17: kourses.com (2026)
A18: White-label add-on norm | B18: $150 – $300 / mo | C18: Full white-label tier; branded mobile app often +$150–200/mo. | D18: kourses.com (2026)
A19: THE STACK A BUYER ACTUALLY REPLACES
A20: Small institute | B20: ≈ ₹22,500 / mo | C20: Classplus at ₹15,000 + LeadSquared Pro × 3 seats at ₹2,500. | D20: Derived from the rows above
A21: Growing institute | B21: ≈ ₹51,000 / mo | C21: Classplus at ₹15,000 + LeadSquared Super × 8 seats at ₹4,500. | D21: Derived from the rows above
A22: Multi-branch group | B22: ≈ ₹2,15,000 / mo | C22: Teachmint at ₹1,25,000 + LeadSquared Super × 20 seats at ₹4,500. | D22: Derived from the rows above
A24: Read across, not down: no vendor here sells LMS + institute CRM + placement + AI mocks as one product. The last block is the comparison a buyer actually makes — and it is the number our licence should be quoted against, not the Classplus line on its own.

Sheet Sensitivity
A1: What breaks the margin
A2: Growth tier at the recommended India price. Two levers matter, and only two.
A4: Lever 1 — voice minutes given away inside the licence
A5: Included voice minutes / mo | B5: Included AI cost (USD) | C5: Total tenant cost (USD) | D5: Margin at ₹74,999
A6: 0 | B6: =100*'Unit economics'!$C$16+A6*(Assumptions!$B$24+Assumptions!$B$25) | C6: ='Tier economics'!$D$6+'Tier economics'!$E$6+B6 | D6: =IFERROR((('Tier economics'!$H$6/Assumptions!$B$6)-C6)/('Tier economics'!$H$6/Assumptions!$B$6),0)
A7: 400 | B7: =100*'Unit economics'!$C$16+A7*(Assumptions!$B$24+Assumptions!$B$25) | C7: ='Tier economics'!$D$6+'Tier economics'!$E$6+B7 | D7: =IFERROR((('Tier economics'!$H$6/Assumptions!$B$6)-C7)/('Tier economics'!$H$6/Assumptions!$B$6),0)
A8: 1000 | B8: =100*'Unit economics'!$C$16+A8*(Assumptions!$B$24+Assumptions!$B$25) | C8: ='Tier economics'!$D$6+'Tier economics'!$E$6+B8 | D8: =IFERROR((('Tier economics'!$H$6/Assumptions!$B$6)-C8)/('Tier economics'!$H$6/Assumptions!$B$6),0)
A9: 2500 | B9: =100*'Unit economics'!$C$16+A9*(Assumptions!$B$24+Assumptions!$B$25) | C9: ='Tier economics'!$D$6+'Tier economics'!$E$6+B9 | D9: =IFERROR((('Tier economics'!$H$6/Assumptions!$B$6)-C9)/('Tier economics'!$H$6/Assumptions!$B$6),0)
A10: 5000 | B10: =100*'Unit economics'!$C$16+A10*(Assumptions!$B$24+Assumptions!$B$25) | C10: ='Tier economics'!$D$6+'Tier economics'!$E$6+B10 | D10: =IFERROR((('Tier economics'!$H$6/Assumptions!$B$6)-C10)/('Tier economics'!$H$6/Assumptions!$B$6),0)
A11: 10000 | B11: =100*'Unit economics'!$C$16+A11*(Assumptions!$B$24+Assumptions!$B$25) | C11: ='Tier economics'!$D$6+'Tier economics'!$E$6+B11 | D11: =IFERROR((('Tier economics'!$H$6/Assumptions!$B$6)-C11)/('Tier economics'!$H$6/Assumptions!$B$6),0)
A13: 400 minutes is the recommended Growth allowance — about 27 mock interviews a month, enough for the partner to see the product work. Give away 2,500 and the tier is barely profitable; give away 5,000 and it is not. This is the single most expensive concession a salesperson can make, so it belongs in the order form, not in a conversation.
A15: Lever 2 — how many enrolled seats are actually active
A16: Monthly-active share | B16: Active seats | C16: Platform cost (USD) | D16: Total tenant cost (USD) | E16: Margin at ₹74,999
A17: 0.4 | B17: ='Tier economics'!$B$6*A17 | C17: =B17*'Unit economics'!$C$10 | D17: =C17+'Tier economics'!$E$6+'Tier economics'!$F$6 | E17: =IFERROR((('Tier economics'!$H$6/Assumptions!$B$6)-D17)/('Tier economics'!$H$6/Assumptions!$B$6),0)
A18: 0.55 | B18: ='Tier economics'!$B$6*A18 | C18: =B18*'Unit economics'!$C$10 | D18: =C18+'Tier economics'!$E$6+'Tier economics'!$F$6 | E18: =IFERROR((('Tier economics'!$H$6/Assumptions!$B$6)-D18)/('Tier economics'!$H$6/Assumptions!$B$6),0)
A19: 0.65 | B19: ='Tier economics'!$B$6*A19 | C19: =B19*'Unit economics'!$C$10 | D19: =C19+'Tier economics'!$E$6+'Tier economics'!$F$6 | E19: =IFERROR((('Tier economics'!$H$6/Assumptions!$B$6)-D19)/('Tier economics'!$H$6/Assumptions!$B$6),0)
A20: 0.8 | B20: ='Tier economics'!$B$6*A20 | C20: =B20*'Unit economics'!$C$10 | D20: =C20+'Tier economics'!$E$6+'Tier economics'!$F$6 | E20: =IFERROR((('Tier economics'!$H$6/Assumptions!$B$6)-D20)/('Tier economics'!$H$6/Assumptions!$B$6),0)
A21: 1 | B21: ='Tier economics'!$B$6*A21 | C21: =B21*'Unit economics'!$C$10 | D21: =C21+'Tier economics'!$E$6+'Tier economics'!$F$6 | E21: =IFERROR((('Tier economics'!$H$6/Assumptions!$B$6)-D21)/('Tier economics'!$H$6/Assumptions!$B$6),0)
A23: Platform cost barely moves with utilisation — even at 100% active the margin holds. That is the shape of a software business, and it is the reason seats can be sold generously while minutes cannot.
